Workbook

Sheet Proposed Bets
A1: ID | B1: Created By | C1: Created Date | D1: Bet Description | E1: Offered Moneyline Odds | F1: Maximum Wager | G1: Expiration | H1: Accepting New Bets? | I1: Moneyline formatted | J1: Formatted Max Wager | K1: Expiration Date | L1: Name | M1: Completed | N1: Minimum Bet
H2: FALSE | I2: {=if(len(E2:E10)=0,"",if(E2:E10>=0,"+" & E2:E10,E2:E10))} | J2: {=if(len(F2:F10)=0,"",if(F2:F10>=0,"$" & F2:F10,F2:F10))} | K2: {=IF(LEN(A2:A10) = 0, "", TEXT(G2:G10,"DDD M/D/YY - H:MM AM/PM"))} | L2: {=IF(LEN(A2:A10) = 0, "", vlookup(B2:B10,Profile!B$2:J10,9,false))}
A4: 1319c905-e400-481c-89db-226e9058e55e | B4: rdewling@gmail.com | C4: 44216.69 | D4: Ashby & Zack to def. George & Grady in net, 18 hole, fourball at Sweetens Friday | E4: 100 | F4: 5 | G4: 44225.333 | H4: TRUE | I4: +100 | J4: $5 | K4: Fri 1/29/21 - 8:00 AM | L4: Robby Dewling | M4: TRUE | N4: 1
A5: 1e302d4d-2bbb-40ff-a396-8fe56d1170cc | B5: ar3dson@gmail.com | C5: 44216.736 | D5: A GROSS par occurs before or on the same hole as the first NET par in the foursome on Friday. | E5: 100 | F5: 5 | G5: 44218.25 | H5: TRUE | I5: +100 | J5: $5 | K5: Fri 1/22/21 - 6:00 AM | L5: Alex Edson | M5: TRUE
A6: 3f2c0aff-47a7-4daa-8476-c47b3dcdafb5 | B6: afoltz3@gmail.com | C6: 44224.853 | D6: Any player makes a 4 on #1 | E6: 235 | F6: 15 | G6: 44226.354 | H6: TRUE | I6: +235 | J6: $15 | K6: Sat 1/30/21 - 8:30 AM | L6: Ashby Foltz | M6: TRUE
A7: ca641c4b-55c6-42c9-9610-25224a806a50 | B7: rburnsgt@gmail.com | C7: 44224.855 | D7: I bet GME is over 375 at noon Eastern time 12/29 | E7: 100 | F7: 10 | G7: 44224.999 | H7: TRUE | I7: +100 | J7: $10 | K7: Thu 1/28/21 - 11:58 PM | L7: Rob Burns | M7: FALSE
A9: a95e13ea-9b36-45d9-9ee1-d20a50d5a49a | B9: afoltz3@gmail.com | C9: 44272.804 | D9: Ashby Foltz fails to make the Top 3 for Event 2 | E9: 200 | F9: 35 | G9: 44274.333 | H9: TRUE | I9: +200 | J9: $35 | K9: Fri 3/19/21 - 8:00 AM | L9: Ashby Foltz | M9: TRUE | N9: 10
A10: 9d17a3b1-5dfc-4a4f-a972-82706d80cc27 | B10: afoltz3@gmail.com | C10: 44273.754 | D10: Matt Jones wins the 2021 Honda Classic | E10: 300 | F10: 30 | G10: 44274.292 | H10: TRUE | I10: +300 | J10: $30 | K10: Fri 3/19/21 - 7:00 AM | L10: Ashby Foltz | M10: TRUE | N10: 10

Sheet Accepted Bets
A1: Parent ID | B1: ID | C1: Bet Description | D1: Accepted Wager | E1: Accepted Odds | F1: Offered By (Name) | G1: Accepted On | H1: Accepted By | I1: Completed
A2: 1319c905-e400-481c-89db-226e9058e55e | B2: 8e3939f1-f031-492a-9a1d-4bf9d48c701b | C2: Ashby & Zack to def. George & Grady in net, 18 hole, fourball at Sweetens Friday | D2: 1 | E2: 100 | F2: rdewling@gmail.com | G2: 44216.732 | H2: ar3dson@gmail.com | I2: FALSE
A3: 1e302d4d-2bbb-40ff-a396-8fe56d1170cc | B3: 7e614a34-f34e-4099-9451-e3bf1cc21c6c | C3: A GROSS par occurs before or on the same hole as the first NET par in the foursome on Friday. | D3: 1 | E3: 100 | F3: ar3dson@gmail.com | G3: 44217.501 | H3: rdewling@gmail.com | I3: TRUE
A4: ca641c4b-55c6-42c9-9610-25224a806a50 | B4: dee0b5fe-f496-465c-9ab7-26800089ce78 | C4: I bet GME is over 375 at noon Eastern time 12/29 | D4: 10 | E4: 100 | F4: rburnsgt@gmail.com | G4: 44224.857 | H4: johnprichards3@gmail.com | I4: FALSE
A5: a95e13ea-9b36-45d9-9ee1-d20a50d5a49a | B5: 41ef7fcc-f315-4bdc-aa4a-ca953dd26b37 | C5: Ashby Foltz fails to make the Top 3 for Event 2 | D5: 10 | E5: 200 | F5: afoltz3@gmail.com | G5: 44272.833 | H5: rdewling@gmail.com | I5: TRUE

Sheet Controls
A1: Event Details | C1: Event Types | E1: Order of Operations for updating Event | I1: App Data | J1: Count | L1: Course Data | M1: Count | N1: Net Season Standings Pivot Single Round | O1: Net Season Standings Pivot 2 round | P1: Scratch Season Standings Pivot Single Round | Q1: Scratch Season Standings Pivot 2 Round | R1: Comment | S1: Zapier incrementer | T1: Playoff Round | U1: 1 | V1: Champ Flight Bracket Image | W1: Playing Handicap %
A2: Current Event Type | B2: M | C2: R18 | E2: 1) Turn off Zapier | I2: Courses | J2: {=COUNTA(Courses!$A$3:$A1001)} -> 794 | L2: 0 Rounds | M2: {=COUNTIF(Courses!$K$3:$K1001,"=0")} -> 659 | N2: if(min('Net Score')>0, concatenate("+", min('Net Score')), (if(min('Net Score')=0, "E", min('Net Score')))) | O2: if(min(iferror(small('Net Score',2)+min('Net Score'),min('Net Score')))>0, concatenate("+", min(iferror(small('Net Score',2)+min('Net Score'),min('Net Score')))), (if(min(iferror(small('Net Score',2)+min('Net Score'),min('Net Score')))=0, "E", min(iferror(small('Net Score',2)+min('Net Score'),min('Net Score')))))) | P2: if(min('Scratch Score')>0, concatenate("+", min('Scratch Score')), (if(min('Scratch Score')=0, "E", min('Scratch Score')))) | Q2: if(min(iferror(small('Scratch Score',2)+min('Scratch Score'),min('Scratch Score')))>0, concatenate("+", min(iferror(small('Scratch Score',2)+min('Scratch Score'),min('Scratch Score')))), (if(min(iferror(small('Scratch Score',2)+min('Scratch Score'),min('Scratch Score')))=0, "E", min(iferror(small('Scratch Score',2)+min('Scratch Score'),min('Scratch Score')))))) | S2: 12 | T2: 3 | V2: https://lh3.googleusercontent.com/pw/AP1GczPqLBJkUhINRnD14ITdLiz8wH_diUPDC04OnVlzlXNUWr-TLTtGzoUgCQwGNw_oRDtwFbL0qWwmOp8SUSkOjFwCEjjDz5BqSw9eQ5MWAt5suPldsLGM7mg5WsW_YB3zCRJC7HLR_kffa0CUSGBLWA5QZw=w839-h602-s-no-gm?authuser=0 | W2: 0.95
A3: Current Event Name | B3: 12 | C3: R9 | E3: 1.5) Delete incomplete scores | I3: Current Event Scores | J3: {=COUNTA('Current Event Scores'!$A$2:$A1001)} -> 51 | L3: 1 Round | M3: {=COUNTIF(Courses!$K$3:$K1001,"=1")} -> 81
C4: M | E4: 2) Take event leaderboard screenshots | I4: Net + Scratch Season Standings | J4: {=COUNTA('Net + Scratch Season Standings'!$A$2:$A1001)} -> 15 | L4: 2+ Rounds | M4: {=COUNTIF(Courses!$K$3:$K1001,">1")} -> 43
C5: C | E5: 3) Archive scores & reset round history | I5: Scratch Season Standings | J5: {=COUNTA('Scratch Season Standings'!$A$2:$A1001)} -> 15
E6: 4) Delete old scores | I6: Profile | J6: {=COUNTA(Profile!$B$3:$B1001)} -> 22
E7: 5) Update Controls to new event type (and playoffs) | I7: Home | J7: {=COUNTA(Home!$B$2:$B1001)} -> 1
E8: 6) Turn on Zapier | I8: Net Leaderboard | J8: {=COUNTA('Net Leaderboard'!$B$3:$B1001)} -> 8
E9: 7) Update handicaps | I9: Scratch Leaderboard | J9: {=COUNTA('Scratch Leaderboard'!$B$3:B1001)} -> 8
E10: 8) Update SITS | I10: FAQ | J10: {=COUNTA(FAQ!$A$2:A1001)} -> 2
E11: 9) Take season leaderboard screenshots | I11: Score Images | J11: {=COUNTA('Score Images'!$A$2:A1001)} -> 116
I12: Types | J12: {=COUNTA(Types!$B$2:B1001)} -> 4
I13: SUM | J13: =SUM(J2:J12) -> 1036

Sheet Home
A1: Announcement | B1: Title | C1: Welcome | D1: Message | E1: Header Image | F1: Season Standings | G1: Event Standings | H1: Photos | I1: News | J1: Home page | K1: Schedule | L1: Bobby Jones Cup Video | M1: Lookup Course Rating | N1: Pay Now | O1: Pro Shop | P1: MT 2020 Video | Q1: Slack Link | R1: Rating/Slope Guidance | S1: Course DB Screenshot | U1: MT Logo | V1: Zapier | W1: Photo Random Number | X1: Random Photo URL | Y1: Current Event Name | Z1: Event Type Code | AA1: Playoffs On/Off | AB1: Playoffs Bracket Image URL
B2: Minerva Tour | C2: Welcome to the Minerva Tour | D2: Start a round or edit your scores below. Other member's scores can be edited on the "Scores" tab | E2: https://lh3.googleusercontent.com/e_MgqK4-JHYTWRZFI8DXHiDneYfOF6u3ym0BS4AJ8hmgQQ5K9oSutD6migdiwQsUqtK_UI2RndYhwyw7RMVDe4AUwX86WnXpPSfBVWri8tfbx-Hz4KnsY0s2vdW0XtuIOQWi3r48h0GF4ABtBojiWiat5f74w1kOpswa-jv7mNB7kKIMPxoti5HfaLsFa_w5ZncLB_Var_x52iup6EeAdoPDY3m1jN5CJSDKohz6S3CV1j_XeQ9MyaA5jDwBnshME6mMJT1kmY6GVNL_LoOo_yYRcKIzN8vld2NQxOmPcJwMxZH0QkIfGBGAeReDfpgC4-fIo2elq7hpfpxReaUtpOWOMAzgrKU-y9plKXqCU-sOXX5y8hduqnfPmTL8Vl2Nmf7PW4fARzATCUcYEweDsy_2nE6fuwpbTL2r0v280fqCub1JYd7QligcZvFWJ-unKZL0HydpBJXpORAmUos0vjeHSCo_MkO1b0v8TpGRWdxQ-cJOL08W8Np-THCTvlT8321DXxFpyVy2qzR09UjyMoAgHuvjlC-1o-hhKmGhYmMgV892ahhsaA-jJ7Ny3q6T_88hciBI64UdtzOlwvGRR_S6ZzDOu3uJdXokZcP_QCm59ystfDC4Y3FwsLvDm76V-MtlZJpGnKuEhJLCodBElZBVdPKyc6px5Gg2TIGiYVeBkTb5tXSiMRBRV7-_YsZgxGlpfd1AOvepHNgGmcyXrKqiV2udfukZ8RNfCXOmB4XEm3jR=w1440-h700-no | F2: https://minervatour.wordpress.com/leaderboard/ | G2: https://minervatour.wordpress.com/leaderboard/live_event_results/ | H2: https://minervatour.wordpress.com/photos/ | I2: https://minervatour.wordpress.com/?page_id=5 | K2: https://minervatour.wordpress.com/schedule/ | L2: https://www.youtube.com/watch?v=x7VnZXs99xQ | M2: https://ncrdb.usga.org/NCRDB/ | N2: https://venmo.com/code?user_id=1122664177467392174 | O2: https://teamlocker.squadlocker.com/#/lockers/minerva-golf-club?_k=aryzas | P2: https://www.youtube.com/watch?v=_HRq64thRKg | Q2: https://join.slack.com/t/minervagolfclub/shared_invite/enQtOTYwMzk2MzI0NDgyLWEzYTI3YjZhYWJlNDllNTA1YTIyOTM0MWI1ZDNkOTcxNTllYWJmZDQwYmJiNTk4YTkzNGUwZTQ2NDhhZTViZGY | R2: Note: Make sure you enter the correct slope and rating for the course type (18 holes, front 9, or back 9) as these will all have different ratings/slopes. The course rating website link above (or the GHIN app) should include rating/slope for all of these course types. The course rating website only displays properly on mobile browsers if you rotate your phone horizontally (recommend taking a screenshot so you can flip back and forth from app while entering details). To find rating/slope in the GHIN app, go to the "Course Handicap Calculator" select a course, then 18 holes or 9 holes, then tap "Select Tees" | S2: https://lh3.googleusercontent.com/rYzdcO5hQoGhN3vKr6uRn9EKAJex_PukesqJMwDiAZIJg4gfGw-YAnfEazIh8EF7TGEEIMCZ6zL0lCUj5maaIHGjtRDgjKqhrGL091QBzove_wFUZ8sYcPfy6hMBhWDcbqeFPi_7Yez6_gtz3NJAhWpjE98jlKCZktuJDSVmnTKxSQFNobgfAYRozhQfq0e2GigTxtH3wsxqhB9sTYElFxp0x1MzijECE250YukoWWI68CMQZeHPGm179a6_a-2yuEDsjYHCqbY0N4_jsS1llw8kFfsTfB9nbfoEb5ZRsh3BqBKPLqrt_Lm-D8f4lPYgGfD-uHoCnAWj_zsyeWNBxQD5pkvYeltE2ZHyj_G23ll6ixaBOfSUIHwMRJx67_F_kKxmRHbfCEbpLMkwvLGtPKIUj8O05U8BK51Rk2ANEEH7uTSLRx5QN2nq1mqySQZNmTCo8HflE3w56oObG5K1r-VCAasAhYJIEuAGp-ix6H82meKn8fCAy1PY6yCHA1PkiEprRueB7M88G5UsXo9KftCDBzeuvl9M_RYZdp1nOnFHuAmv1hl0f1RQv9wD5ci5hC25_rUNas46TNBCwEzefciW2ZWa3oaeuPM5WKAHN6XlcTwawO7WY9NDkxJIhhyz7Nwg6mZiYyGZQH8dew_tL8w_lqDjSjJ1CGU6GOxquc_hIXn8bcUA3DnW3BIvyzUYrCryy4P5fS-FPnLRvc8zOe-mr_7uCpFKcvFmMmfkzaJQwbbNTGGZfM2M=w3310-h1536-no | U2: https://lh3.googleusercontent.com/pw/AMWts8D0Vykj3F1_p2OewS34q7GS_mwJzVy1QXbCcMtnzUSgjQ1owij00Az6GjtGfAwHTh7Tsv-imxmP1dFpFKnOyndWitW4Qj7PgB60se75fIP7zUp_LiNIrDCpHQU6uA8MZ2mG01Aj7p0jtrnEe8k1cvJKCg=w1822-h1822-s-no?authuser=0 | V2: https://zapier.com/app/dashboard | W2: =randbetween(1,21) -> 9 | X2: =vlookup(W2,Photos!A2:B77,2,false) -> https://lh3.googleusercontent.com/pw/AMWts8C1Ar24hqGSuVtKWcJngs3niVPrKCHG8YD0X66HnaD311HTeNrWtudtMbQ9gsRV-1oZBO1UCYTFAXx8kAjfr_AvyYgooox73yaosObSZG8yrXbj2nccIWCE5_blDNejx9CUr7qJn-_iKok-dUGL7BMPAQ=w1560-h758-s-no?authuser=0 | Y2: =Controls!B3 -> 12 | Z2: =Controls!B2 -> M | AA2: TRUE | AB2: =Controls!V2 -> https://lh3.googleusercontent.com/pw/AP1GczPqLBJkUhINRnD14ITdLiz8wH_diUPDC04OnVlzlXNUWr-TLTtGzoUgCQwGNw_oRDtwFbL0qWwmOp8SUSkOjFwCEjjDz5BqSw9eQ5MWAt5suPldsLGM7mg5WsW_YB3zCRJC7HLR_kffa0CUSGBLWA5QZw=w839-h602-s-no-gm?authuser=0

Sheet Profile
A1: Name | B1: Email Address | C1: Handicap Index | D1: Phone Number | E1: 9 Hole Handicap | F1: Photo | G1: 2017 MT Finish | H1: 2018 MT Finish | I1: 2019 MT FInish | J1: Player Name | K1: Status | L1: Player ID | M1: GHIN Number | N1: Type Filter | O1: NCRDB URL | P1: Trophy Image | Q1: Champ Year | R1: Trophies | S1: 2020 MT Finish | T1: Emojis | U1: Description | V1: Venmo Handle | W1: Web Venmo Deep Link | X1: Venmo Deep Link Prefix | Y1: Venmo User ID | Z1: Apple Deep Link to Venmo | AA1: Android Deep Link | AC1: 🔒 Row ID | AD1: 2021 MT Finish | AE1: 2022 MT Finish | AF1: 2023 MT Finish
E2: {=IF(LEN(C2:C1005) = 0, "",if((C2:C1005) = "NH", "NH", round(C2:C1005/2,1)))} | J2: {=if(len(B2:B1005)=0,"",A2:A1005)} | N2: {=if(len(A2:A1005)=0,"",if(Controls!B2="R9","9 Holes","18 Holes"))} | O2: {=if(len(A2:A1005)=0,"","http://ncrdb.usga.org/")} | W2: {=IF(LEN(A2:A1005)=0,"","https://venmo.com/" & V2:V1005)} | X2: {=IF(LEN(A2:A1005)=0,"","venmo://users/")} | Z2: {=IF(LEN(A2:A1005)=0,"",X2:X1005 & Y2:Y1005)} | AA2: {=IF(LEN(A2:A1005)=0,"","intent://venmo.com/" & V2:V1005 & "#Intent;package=com.venmo;scheme=https;end")}
A3: Blake Addleton | B3: Baddleton@gmail.com | C3: =if(len(B3)=0,"",vlookup(B3,'GG Handicap Import'!$A$2:$E$199,5,false)) -> 14.4 | E3: 7.2 | F3: https://firebasestorage.googleapis.com/v0/b/glide-prod.appspot.com/o/img-uploads%2FGNXfNUSV91nct3RVn9zd%2F26de63.jpeg?alt=media | J3: Blake Addleton | K3: Active | L3: 121 | M3: 10274849 | N3: 18 Holes | O3: http://ncrdb.usga.org/ | T3: 🏆 | U3: Minerva Tour | V3: Blake-Addleton | W3: https://venmo.com/Blake-Addleton | X3: venmo://users/ | Y3: 1254324 | Z3: venmo://users/1254324 | AA3: intent://venmo.com/Blake-Addleton#Intent;package=com.venmo;scheme=https;end | AB3: Active | AC3: RuCU3yUdSzqjzz2KG95B-A
A4: Cory Arnwine | B4: carnwine@gmail.com | C4: =if(len(B4)=0,"",vlookup(B4,'GG Handicap Import'!$A$2:$E$199,5,false)) -> 14.5 | E4: 7.3 | F4: https://storage.googleapis.com/glide-prod.appspot.com/uploads-v2/GNXfNUSV91nct3RVn9zd/pub/ZVOcGslXfVNwGSOfc3Rm.jpeg | G4: 6th | H4: 5th | I4: 2nd | J4: Cory Arnwine | K4: Active | L4: 101 | M4: 2348489 | N4: 18 Holes | O4: http://ncrdb.usga.org/ | Q4: 2018 Most Improved Golfer 2018 Bobby Jones Cup (Hilton Head) 2018 Edge Solutions Cup Playoffs 2019 Bobby Jones Cup (Wisconsin) 2021 Bobby Jones Cup (Michigan) 2022 Minerva Tour Champion | R4: 🏆 📉 🇺🇸🌳🌳 📀 | T4: 📉 | U4: MIG | V4: carnwine | W4: https://venmo.com/carnwine | X4: venmo://users/ | Y4: 531884 | Z4: venmo://users/531884 | AA4: intent://venmo.com/carnwine#Intent;package=com.venmo;scheme=https;end | AB4: Active | AC4: Z19LGmUURuOBxJOMxWptFA
A5: Grady Bunn | B5: grady.bunn@gmail.com | C5: =if(len(B5)=0,"",vlookup(B5,'GG Handicap Import'!$A$2:$E$199,5,false)) -> 13.5 | E5: 6.8 | F5: https://lh3.googleusercontent.com/gQ_FaH2AF_jSJxRNubfcwX3XqG6dcE7KFTHqzUDgdA65lfy57Xnyo2e7D9_ADkXMZDwDprlQ0N8SlSm05CAfkEcLacfWCA0iqKpi5-HBqfCMD3rKMs77CSSzBgDIJPtHWC8lCOtteTiqTljHAcT1-cFtDPSLAC6ryzrYmGoAoI5BlvKRScFk1OMxT2Bz7pWyjn7fkq5GBrAkO1IuaNMgVljRyHjVn3j4j-oL8pGhycJUFlz1nuyea1eDCSU4IwYOfCGfLzodUa4OwrJmuf6CodGiJCB5VR6MYxBUylhMQYa5E-KczOv0t11ByK7uOpvrKtoTdi3tqJvaWgVC0nTYAMlVv7e5sH6_p8vg7h41LS898KW48eXRhJFrAGO2OzZeiy-xOyfD6hxeZ0flReFuhDSrrxF-X-EOf3dMk0FFIcO3TMNC2dzAGzhmpOUwNWKPidDdV_0I2k3dvG7Dguy5auAKUDTJgjgpetzcK5KElhRL-ZdNA6s39BoQgHpB7hsJsw2DZfT2_4ftVj4a-CN6iJdHTdb8QMjIAzCxDiUFlaDUXPHsUo1O8mt6ISJfruKOjsoClx4lDsa_J3M6Bu6h6rojA-_Vu7bbIWAGYFOafxWG3Xq9cqTcI2DGtkLFQg646TzUbrVkNyEGW0xTZxdRUKl7re6bW-F9JbDnigcq-d1XKLtY6P-l7sKdDxo9e-Q9nxMbMaItT4Bio7fNSvFa8gUDuTD_WHt9rtrljgqiOhmxX6Gr=w1250-h937-no | G5: 4th | H5: 13th | I5: 8th | J5: Grady Bunn | K5: Active | L5: 103 | M5: 2348690 | N5: 18 Holes | O5: http://ncrdb.usga.org/ | Q5: 2019 Bobby Jones Cup (Wisconsin) 2020 Bobby Jones Cup (Atlanta) 2023 Bobby Jones Cup (Washington) 2021 Hole in One Club | R5: 1️⃣🌳🌳🌺 | T5: 🎖 | U5: MT Playoff | V5: Grady-Bunn | W5: https://venmo.com/Grady-Bunn | X5: venmo://users/ | Y5: 461096 | Z5: venmo://users/461096 | AA5: intent://venmo.com/Grady-Bunn#Intent;package=com.venmo;scheme=https;end | AB5: Active | AC5: EBAtCrPBTqagwsa5cZ03Wg
A6: Rob Burns | B6: rburnsgt@gmail.com | C6: =if(len(B6)=0,"",vlookup(B6,'GG Handicap Import'!$A$2:$E$199,5,false)) -> 19.2 | E6: 9.6 | F6: https://minervatour.files.wordpress.com/2019/08/img_2701.jpg | G6: 7th | H6: 9th | I6: 10th | J6: Rob Burns | K6: Active | L6: 105 | M6: 2348566 | N6: 18 Holes | O6: http://ncrdb.usga.org/ | Q6: 2017 Unicorn 2020 Bobby Jones Cup (Atlanta) 2021 Unicorn 2022 Bobby Jones Cup (Pinehurst) | R6: 🌳🌳🌺 🦄🦄 | T6: 🍻 | U6: Member-Guest | V6: Rburnsgt | W6: https://venmo.com/Rburnsgt | X6: venmo://users/ | Y6: 446949 | Z6: venmo://users/446949 | AA6: intent://venmo.com/Rburnsgt#Intent;package=com.venmo;scheme=https;end | AB6: Active | AC6: biSEeOiRSDaftic4vVN1rw
A7: Matt Davis | B7: msdavis66@gmail.com | C7: =if(len(B7)=0,"",vlookup(B7,'GG Handicap Import'!$A$2:$E$199,5,false)) -> 17.3 | E7: 8.7 | F7: https://storage.googleapis.com/glide-prod.appspot.com/uploads-v2/GNXfNUSV91nct3RVn9zd/pub/gIt90rSX4ZBQM2wvWa2B.jpeg | H7: 12th | I7: 12th | J7: Matt Davis | K7: Active | L7: 107 | M7: 2357070 | N7: 18 Holes | O7: http://ncrdb.usga.org/ | Q7: 2018 Unicorn 2019 Unicorn | R7: 🦄🦄 | T7: 🌳 | U7: BJC Magnolia | V7: mattdavis66 | W7: https://venmo.com/mattdavis66 | X7: venmo://users/ | Y7: 370401 | Z7: venmo://users/370401 | AA7: intent://venmo.com/mattdavis66#Intent;package=com.venmo;scheme=https;end | AB7: Active | AC7: yluMe1TeRm2KNnZ.uSfTew
A8: Robby Dewling | B8: rdewling@gmail.com | C8: =if(len(B8)=0,"",vlookup(B8,'GG Handicap Import'!$A$2:$E$199,5,false)) -> 6.1 | D8: 678-491-7196 | E8: 3.1 | F8: https://storage.googleapis.com/glide-prod.appspot.com/uploads-v2/GNXfNUSV91nct3RVn9zd/pub/wD9y0NT35v2ch7ZEGxQP.jpeg | G8: 1st | H8: 8th | I8: 4th | J8: Robby Dewling | K8: Active | L8: 108 | M8: 2348438 | N8: 18 Holes | O8: http://ncrdb.usga.org/ | P8: https://cdn3.iconfinder.com/data/icons/business-631/50/54-512.png | Q8: 2017 Minerva Tour Champion 2018 Bobby Jones Cup (Hilton Head) 2019 Member-Guest (Chattanooga) 2021 Minerva Tour Champion 2021 Most Improved Golfer 2021 Bobby Jones Cup (Michigan) 2022 Member-Guest (Chattanooga) 2022 Bobby Jones Cup (Pinehurst) 2024 Minerva Tour Champion 2024 Most Improved Golfer 2024 Bobby Jones Cup (Streamsong) | R8: 🏆🏆🏆 🍻🍻 🇺🇸🌳🌳🌺 📉📉 | T8: 🌺 | U8: Scratch | V8: Robby-Dewling | W8: https://venmo.com/Robby-Dewling | X8: venmo://users/ | Y8: 254183 | Z8: venmo://users/254183 | AA8: intent://venmo.com/Robby-Dewling#Intent;package=com.venmo;scheme=https;end | AB8: Active | AC8: 6N4m2687QX23qNxBaCEfWQ
A9: Alex Edson | B9: ar3dson@gmail.com | C9: =if(len(B9)=0,"",vlookup(B9,'GG Handicap Import'!$A$2:$E$199,5,false)) -> 7.6 | E9: 3.8 | F9: https://storage.googleapis.com/glide-prod.appspot.com/uploads-v2/GNXfNUSV91nct3RVn9zd/pub/MXbvc7EbvlbCRBjsPjcA.jpg | H9: 4th | I9: 7th | J9: Alex Edson | K9: Active | L9: 109 | M9: 2357064 | N9: 18 Holes | O9: http://ncrdb.usga.org/ | Q9: 2019 Bobby Jones Cup (Wisconsin) 2020 Bobby Jones Cup (Atlanta) 2020 Scratch Champion 2021 Member-Guest 2022 Bobby Jones Cup (Pinehurst) 2025 Member-Guest | R9: 🥇 🍻🍻 🌳🌳🌳 | T9: 🥇 | U9: Hole In One | V9: Alex-Edson | W9: https://venmo.com/Alex-Edson | X9: venmo://users/ | Y9: 1180653 | Z9: venmo://users/1180653 | AA9: intent://venmo.com/Alex-Edson#Intent;package=com.venmo;scheme=https;end | AB9: Active | AC9: NcrCZJOoScW4cI6qHK78aQ
A10: Ashby Foltz | B10: afoltz3@gmail.com | C10: =if(len(B10)=0,"",vlookup(B10,'GG Handicap Import'!$A$2:$E$199,5,false)) -> 17.8 | E10: 8.9 | F10: https://minervatour.files.wordpress.com/2019/10/img_5277.jpg | G10: 3rd | H10: 2nd | I10: 1st | J10: Ashby Foltz | K10: Active | L10: 110 | M10: 2348481 | N10: 18 Holes | O10: http://ncrdb.usga.org/ | P10: https://cdn3.iconfinder.com/data/icons/business-631/50/54-512.png | Q10: 2018 Hole in One Club 2019 Minerva Tour Champion 2020 Minerva Tour Champion 2020 Bobby Jones Cup (Atlanta) 2022 Bobby Jones Cup (Pinehurst) 2023 Minerva Tour Champion 2023 Bobby Jones Cup (Washington) 2024 Bobby Jones Cup (Streamsong) | R10: 🏆🏆🏆 🌳🌳🌺🌺 1️⃣ | T10: 1️⃣ | U10: Unicorn | V10: ashbyfoltz | W10: https://venmo.com/ashbyfoltz | X10: venmo://users/ | Y10: 262782 | Z10: venmo://users/262782 | AA10: intent://venmo.com/ashbyfoltz#Intent;package=com.venmo;scheme=https;end | AB10: Active | AC10: qi7MxjvwThWbw4Zf-3rIhA
A12: Nick Johnson | B12: nick.johnson810@gmail.com | C12: =if(len(B12)=0,"",vlookup(B12,'GG Handicap Import'!$A$2:$E$199,5,false)) -> 28.6 | E12: 14.3 | F12: https://storage.googleapis.com/glide-prod.appspot.com/uploads-v2/GNXfNUSV91nct3RVn9zd/pub/cvpSy2z837uKSKvlZm1n.jpeg | J12: Nick Johnson | K12: Active | L12: 119 | M12: 10275275 | N12: 18 Holes | O12: http://ncrdb.usga.org/ | Q12: 2023 Bobby Jones Cup (Washington) 2024 Bobby Jones Cup (Streamsong) | R12: 🌺🌺 | T12: 🥈 | V12: Nick-Johnson | W12: https://venmo.com/Nick-Johnson | X12: venmo://users/ | Y12: 83159 | Z12: venmo://users/83159 | AA12: intent://venmo.com/Nick-Johnson#Intent;package=com.venmo;scheme=https;end | AB12: Active | AC12: Teef9OstSBWouf14PIUmdQ
A13: George Lane | B13: gmlane@gmail.com | C13: =if(len(B13)=0,"",vlookup(B13,'GG Handicap Import'!$A$2:$E$199,5,false)) -> 10.7 | E13: 5.4 | F13: https://firebasestorage.googleapis.com/v0/b/glide-prod.appspot.com/o/img-uploads%2FGNXfNUSV91nct3RVn9zd%2Fb607eb.jpeg?alt=media | H13: 10th | I13: 3rd | J13: George Lane | K13: Active | L13: 113 | M13: 2699107 | N13: 18 Holes | O13: http://ncrdb.usga.org/ | Q13: 2018 Bobby Jones Cup (Hilton Head) 2019 Most Improved Golfer 2020 Most Improved Golfer 2023 Most Improved Golfer 2021 Scratch Champion 2022 Member-Guest (Chattanooga) | R13: 🥇 🍻 📉📉📉 🇺🇸 | V13: George-Lane | W13: https://venmo.com/George-Lane | X13: venmo://users/ | Y13: 469077 | Z13: venmo://users/469077 | AA13: intent://venmo.com/George-Lane#Intent;package=com.venmo;scheme=https;end | AB13: Active | AC13: jUcVdXt6TuqTOxO9bzKlUA
A14: Marc Mastrangelo | B14: mastrangeloms@gmail.com | C14: =if(len(B14)=0,"",vlookup(B14,'GG Handicap Import'!$A$2:$E$199,5,false)) -> 27.3 | E14: 13.7 | F14: https://storage.googleapis.com/glide-prod.appspot.com/uploads-v2/GNXfNUSV91nct3RVn9zd/pub/AnT30ERyS1NLw6e1i8mo.jpeg | J14: Marc Mastrangelo | K14: Active | L14: 124 | M14: 10477569 | N14: 18 Holes | O14: http://ncrdb.usga.org/ | Q14: 2020 Minerva Tour Playoffs 2021 Consolation Winner | R14: 🎖 🥈 | V14: Marc-Mastrangelo | W14: https://venmo.com/Marc-Mastrangelo | X14: venmo://users/ | Y14: 2576643 | Z14: venmo://users/2576643 | AA14: intent://venmo.com/Marc-Mastrangelo#Intent;package=com.venmo;scheme=https;end | AB14: Active | AC14: 0KGiHN87QYeAmCVAZvE.Bw
A16: David Mustard | B16: dmustard@gmail.com | C16: =if(len(B16)=0,"",vlookup(B16,'GG Handicap Import'!$A$2:$E$199,5,false)) -> 10.6 | E16: 5.3 | F16: https://firebasestorage.googleapis.com/v0/b/glide-prod.appspot.com/o/img-uploads%2FGNXfNUSV91nct3RVn9zd%2F0c43b8.jpeg?alt=media | J16: David Mustard | K16: Active | L16: 122 | M16: 2155192 | N16: 18 Holes | O16: http://ncrdb.usga.org/ | Q16: 2019 Member-Guest (Chattanooga) | R16: 🍻 | V16: Charlotte-Mustard | W16: https://venmo.com/Charlotte-Mustard | X16: venmo://users/ | Y16: 15137483 | Z16: venmo://users/15137483 | AA16: intent://venmo.com/Charlotte-Mustard#Intent;package=com.venmo;scheme=https;end | AB16: Active | AC16: 6YX83ugSQ3e-GSJQgE9g9Q
A17: John Richards | B17: johnprichards3@gmail.com | C17: =if(len(B17)=0,"",vlookup(B17,'GG Handicap Import'!$A$2:$E$199,5,false)) -> 24.2 | E17: 12.1 | F17: https://storage.googleapis.com/glide-prod.appspot.com/uploads-v2/GNXfNUSV91nct3RVn9zd/pub/Tk2HdqDt4NKfTiKK87oY.jpeg | J17: John Richards | K17: Active | L17: 126 | M17: 10662253 | N17: 18 Holes | O17: http://ncrdb.usga.org/ | Q17: 2021 Bobby Jones Cup (Michigan) 2022 Most Improved Golfer 2023 Member-Guest (Alabama) 2024 Member-Guest (Aiken) | R17: 🍻🍻 📉 🌳 | V17: johnrichards | W17: https://venmo.com/johnrichards | X17: venmo://users/ | Y17: 213962 | Z17: venmo://users/213962 | AA17: intent://venmo.com/johnrichards#Intent;package=com.venmo;scheme=https;end | AB17: Active | AC17: UH3acsGsSGKXlUvMH0BGPQ
A18: Bobby Ross | B18: saebobbyross@gmail.com | C18: =if(len(B18)=0,"",vlookup(B18,'GG Handicap Import'!$A$2:$E$199,5,false)) -> 16.2 | E18: 8.1 | F18: https://firebasestorage.googleapis.com/v0/b/glide-prod.appspot.com/o/img-uploads%2FGNXfNUSV91nct3RVn9zd%2F7ede3f.jpeg?alt=media | G18: 2nd | H18: 3rd | I18: 6th | J18: Bobby Ross | K18: Active | L18: 115 | M18: 2348449 | N18: 18 Holes | O18: http://ncrdb.usga.org/ | Q18: 2018 Bobby Jones Cup (Hilton Head) 2019 Bobby Jones Cup (Wisconsin) 2019 Minerva Tour Playoffs 2020 Hole in One Club 2021 Bobby Jones Cup (Michigan) | R18: 🎖 🇺🇸🌳🌳 1️⃣ | V18: Bobby-Ross | W18: https://venmo.com/Bobby-Ross | X18: venmo://users/ | Y18: 3192633 | Z18: venmo://users/3192633 | AA18: intent://venmo.com/Bobby-Ross#Intent;package=com.venmo;scheme=https;end | AB18: Active | AC18: wTidpxgQTGyqEJeS8ltJkg
C19: =if(len(B19)=0,"",vlookup(B19,'GG Handicap Import'!$A$2:$E$199,5,false))
A20: Hastings Westphal | B20: vhwestphal@gmail.com | C20: =if(len(B20)=0,"",vlookup(B20,'GG Handicap Import'!$A$2:$E$199,5,false)) -> 12.9 | E20: 6.5 | F20: https://firebasestorage.googleapis.com/v0/b/glide-prod.appspot.com/o/img-uploads%2FGNXfNUSV91nct3RVn9zd%2Ffdee84.jpeg?alt=media | H20: 1st | I20: 5th | J20: Hastings Westphal | K20: Active | L20: 118 | M20: 2530813 | N20: 18 Holes | O20: http://ncrdb.usga.org/ | P20: https://cdn3.iconfinder.com/data/icons/business-631/50/54-512.png | Q20: 2018 Minerva Tour Champion | R20: 🏆 | V20: Val-Westphal | W20: https://venmo.com/Val-Westphal | X20: venmo://users/ | Y20: 264192 | Z20: venmo://users/264192 | AA20: intent://venmo.com/Val-Westphal#Intent;package=com.venmo;scheme=https;end | AB20: Active | AC20: DIdea5lgTCOen2npbRopLA
A21: Zack Taylor | B21: zackpetaylor@gmail.com | C21: =if(len(B21)=0,"",vlookup(B21,'GG Handicap Import'!$A$2:$E$199,5,false)) -> 10.4 | E21: 5.2 | F21: https://minervatour.files.wordpress.com/2019/03/img_4492.jpg?w=478&h=&zoom=2 | J21: Zack Taylor | K21: Active | L21: 125 | M21: 3198866 | N21: 18 Holes | O21: http://ncrdb.usga.org/ | Q21: 2020 Bobby Jones Cup (Atlanta) | R21: 🌳 | V21: Zack-Taylor-1 | W21: https://venmo.com/Zack-Taylor-1 | X21: venmo://users/ | Y21: 811104 | Z21: venmo://users/811104 | AA21: intent://venmo.com/Zack-Taylor-1#Intent;package=com.venmo;scheme=https;end | AB21: Active | AC21: MP3Nk.raRXCC1.sdoEAaEg
A22: Devin Blankenship | B22: blankdc.db@gmail.com | C22: =if(len(B22)=0,"",vlookup(B22,'GG Handicap Import'!$A$2:$E$199,5,false)) -> 6.7 | E22: 3.4 | F22: https://storage.googleapis.com/glide-prod.appspot.com/uploads-v2/GNXfNUSV91nct3RVn9zd/pub/3IF1Dcz5QrdTlzpion8b.jpeg | J22: Devin Blankenship | K22: Active | L22: 127 | M22: 10239037 | N22: 18 Holes | O22: http://ncrdb.usga.org/ | Q22: 2022 Scratch Champion 2023 Scratch Champion 2024 Scratch Champion | R22: 🥇🥇🥇 | W22: https://venmo.com/ | X22: venmo://users/ | Z22: venmo://users/ | AA22: intent://venmo.com/#Intent;package=com.venmo;scheme=https;end | AC22: qukHyIawROiuH9aKBSnh0g
A23: Bryan Chiodo | B23: Blchiodo@gmail.com | C23: =if(len(B23)=0,"",vlookup(B23,'GG Handicap Import'!$A$2:$E$199,5,false)) -> 16.6 | E23: 8.3 | F23: https://lh3.googleusercontent.com/pw/AP1GczOlTxwPpjvglsYR6B0r2-TBnLRnyfdUcF32EvLVlEADtDz_6wIOkLczpPDSiOzkuPbKclhqy0DipfukCyD0lCmsG4HIYsHS78j3EQekQniI9XDh8XPXUvR-gd9CPktBx8yUk2mbqYFaQE-poffErs3uqQ=w644-h934-s-no-gm?authuser=0 | J23: Bryan Chiodo | K23: Active | M23: 10256142 | N23: 18 Holes | O23: http://ncrdb.usga.org/ | W23: https://venmo.com/ | X23: venmo://users/ | Z23: venmo://users/ | AA23: intent://venmo.com/#Intent;package=com.venmo;scheme=https;end | AC23: uhV5JFqURI-AOmsToy4qvA
A24: Jeff DeLong | B24: jeffdelong12@gmail.com | C24: =if(len(B24)=0,"",vlookup(B24,'GG Handicap Import'!$A$2:$E$199,5,false)) -> 32.4 | E24: 16.2 | F24: https://storage.googleapis.com/glide-prod.appspot.com/uploads-v2/GNXfNUSV91nct3RVn9zd/pub/rpwwzvzI6V08QdD0rba1.jpeg | J24: Jeff DeLong | K24: Active | N24: 18 Holes | O24: http://ncrdb.usga.org/ | W24: https://venmo.com/ | X24: venmo://users/ | Z24: venmo://users/ | AA24: intent://venmo.com/#Intent;package=com.venmo;scheme=https;end | AC24: KOVGGv7FQn-sj55ohF8Dbg
C25: =if(len(B25)=0,"",vlookup(B25,'GG Handicap Import'!$A$2:$E$199,5,false))
C26: =if(len(B26)=0,"",vlookup(B26,'GG Handicap Import'!$A$2:$E$199,5,false))
C27: =if(len(B27)=0,"",vlookup(B27,'GG Handicap Import'!$A$2:$E$199,5,false))
C28: =if(len(B28)=0,"",vlookup(B28,'GG Handicap Import'!$A$2:$E$199,5,false))
C29: =if(len(B29)=0,"",vlookup(B29,'GG Handicap Import'!$A$2:$E$199,5,false))
C30: =if(len(B30)=0,"",vlookup(B30,'GG Handicap Import'!$A$2:$E$199,5,false))
C31: =if(len(B31)=0,"",vlookup(B31,'GG Handicap Import'!$A$2:$E$199,5,false))
C32: =if(len(B32)=0,"",vlookup(B32,'GG Handicap Import'!$A$2:$E$199,5,false))
C33: =if(len(B33)=0,"",vlookup(B33,'GG Handicap Import'!$A$2:$E$199,5,false))
C34: =if(len(B34)=0,"",vlookup(B34,'GG Handicap Import'!$A$2:$E$199,5,false))
C35: =if(len(B35)=0,"",vlookup(B35,'GG Handicap Import'!$A$2:$E$199,5,false))
C36: =if(len(B36)=0,"",vlookup(B36,'GG Handicap Import'!$A$2:$E$199,5,false))
... C63: =if(len(B63)=0,"",vlookup(B63,'GG Handicap Import'!$A$2:$E$199,5,false))
B1003: dailey.dewling@gmail.com | AC1003: qvBruV93ROu9uH5Ztb7vrQ
B1004: stevo0718@gmail.com | AC1004: VO5wPDHSRb6V8xNnyd-ZUg
B1005: fiery-jelly-090@anonymous.appuser.io | AC1005: FErkXHSwQSmqdHsukPEzLA

Sheet GG Handicap Import
A1: Email | B1: First Name | C1: Last Name | D1: Handle | E1: Index | F1: GHIN Id | G1: Registration Status | H1: Affiliation | I1: Date of Birth | J1: Gender | K1: Tee | L1: Registration Member or Guest | M1: Team Id | N1: Entry Number | O1: Pro or Amateur | P1: Riding / Walking / Caddie | Q1: address1 | R1: address2 | S1: city | T1: GHIN Active | Z1: GHIN Number | AA1: Golfer Name | AB1: Current | AC1: 45748 | AD1: 45717 | AE1: 45689 | AF1: 45658 | AG1: 45627 | AH1: 45597 | AI1: 45566 | AJ1: 45536 | AK1: 45505 | AL1: 45474 | AM1: 45444 | AN1: 45413
A2: baddleton@gmail.com | B2: Blake | C2: Addleton | D2: Blake Addleton | E2: 14.4 | F2: 10274849 | G2: Confirmed | H2: Minerva Golf Club | I2: 32899 | J2: M | L2: member | M2: 10 | N2: 10 | Q2: 3905 Weber Way | S2: Lexington | T2: Yes | Z2: 10274849 | AA2: Blake Addleton | AB2: 14.4 | AC2: 14.4 | AD2: 14.6 | AE2: 14.6 | AF2: 15.2 | AG2: 15.2 | AH2: 15.2 | AI2: 15.2 | AJ2: 15.2 | AK2: 15.1 | AL2: 14.8 | AM2: 15.4 | AN2: 14.4
A3: carnwine@gmail.com | B3: Cory | C3: Arnwine | D3: Cory Arnwine | E3: 14.5 | F3: 2348489 | G3: Confirmed | H3: Minerva Golf Club | I3: 32210 | J3: M | L3: member | M3: 7 | N3: 7 | Q3: 804 Walnut Avenue | S3: Charlotte | T3: Yes | Z3: 2348489 | AA3: Cory Arnwine | AB3: 13.7 | AC3: 13.7 | AD3: 13.7 | AE3: 13.7 | AF3: 13.7 | AG3: 13.7 | AH3: 13.7 | AI3: 13.7 | AJ3: 13.4 | AK3: 13 | AL3: 13 | AM3: 12.8 | AN3: 12.8
A4: blankdc.db@gmail.com | B4: Devin | C4: Blankenship | D4: Devin Blankenship | E4: 6.7 | F4: 10239037 | G4: Confirmed | H4: Horseshoe Bend Country Club | J4: M | L4: guest | M4: 22 | N4: 22 | T4: Yes | Z4: 12247571 | AA4: Justin Brown | AB4: 27.6 | AC4: 27.6 | AD4: 27.6 | AE4: 27.6 | AF4: 27.6 | AG4: 27.6 | AH4: 27.6 | AI4: 27.6 | AJ4: 27.6 | AK4: 27.6 | AL4: 27.6 | AM4: 27.6 | AN4: 27.6
A5: grady.bunn@gmail.com | B5: Grady | C5: Bunn | D5: Grady Bunn | E5: 13.5 | F5: 2348690 | G5: Confirmed | H5: Minerva Golf Club | I5: 32501 | J5: M | L5: member | M5: 13 | N5: 13 | Q5: 1873 Bragg St | S5: Chamblee | T5: Yes | Z5: 2348690 | AA5: Grady Bunn | AB5: 13.5 | AC5: 13.6 | AD5: 13.6 | AE5: 13.6 | AF5: 13.6 | AG5: 12.7 | AH5: 12.6 | AI5: 12.6 | AJ5: 12.6 | AK5: 12.6 | AL5: 15.5 | AM5: 15.7 | AN5: 15.7
A6: rburnsgt@gmail.com | B6: Rob | C6: Burns | D6: Rob Burns | E6: 19.2 | F6: 2348566 | G6: Confirmed | H6: Minerva Golf Club | I6: 32658 | J6: M | L6: member | M6: 18 | N6: 18 | Q6: 2719 Green Meadows Ln NE | S6: Brookhaven | T6: Yes | Z6: 2348566 | AA6: Rob Burns | AB6: 19.2 | AC6: 19.2 | AD6: 19.2 | AE6: 19.2 | AF6: 19.2 | AG6: 19.2 | AH6: 19.2 | AI6: 19.9 | AJ6: 19.9 | AK6: 19.9 | AL6: 20.8 | AM6: 20.8 | AN6: 20.8
A7: blchiodo@gmail.com | B7: Bryan | C7: Chiodo | D7: Bryan Chiodo | E7: 16.6 | F7: 10256142 | G7: Confirmed | H7: USGA/GSGA GC | J7: M | L7: guest | M7: 27 | N7: 27 | S7: CUMMING | T7: Yes | Z7: 2357070 | AA7: Matt Davis | AB7: 17.8 | AC7: 18.2 | AD7: 18.2 | AE7: 18.2 | AF7: 18.2 | AG7: 18.2 | AH7: 18.2 | AI7: 18.4 | AJ7: 18.4 | AK7: 19.6 | AL7: 19.6 | AM7: 19.6 | AN7: 19.6
A8: msdavis66@gmail.com | B8: Matt | C8: Davis | D8: Matt Davis | E8: 17.3 | F8: 2357070 | G8: Confirmed | H8: Minerva Golf Club | I8: 33121 | J8: M | L8: member | M8: 16 | N8: 16 | Q8: 360 W 47th St | R8: Apt 4a | S8: New York | T8: Yes | Z8: 11689546 | AA8: Jeff DeLong | AB8: 32.4 | AC8: 32.4 | AD8: 32.4 | AE8: 32.4 | AF8: 32.4 | AG8: 32.4 | AH8: 32.2 | AI8: 32.2 | AJ8: 32.2 | AK8: 32.2 | AL8: 32.2 | AM8: 31.2 | AN8: 31.2
A9: jeffdelong12@gmail.com | B9: Jeff | C9: DeLong | D9: Jeff DeLong | E9: 32.4 | F9: 11689546 | G9: Confirmed | H9: Minerva Golf Club | J9: M | L9: member | M9: 24 | N9: 24 | T9: Yes | Z9: 2348438 | AA9: Robby Dewling | AB9: 7.9 | AC9: 7.3 | AD9: 7.3 | AE9: 7.7 | AF9: 7.7 | AG9: 7.7 | AH9: 7.7 | AI9: 8.8 | AJ9: 8.8 | AK9: 9.3 | AL9: 11.4 | AM9: 11.7 | AN9: 12.5
A10: rdewling@gmail.com | B10: Robby | C10: Dewling | D10: Robby Dewling | E10: 6.1 | F10: 2348438 | G10: Confirmed | H10: Minerva Golf Club | I10: 32723 | J10: M | L10: member | M10: 9 | N10: 9 | Q10: 381 Hascall Road Northwest | S10: Atlanta | T10: Yes | Z10: 2357064 | AA10: Alex Edson | AB10: 10.8 | AC10: 10.9 | AD10: 9.5 | AE10: 9.6 | AF10: 9.6 | AG10: 9.9 | AH10: 9.7 | AI10: 9.7 | AJ10: 9.7 | AK10: 9.7 | AL10: 9.7 | AM10: 9.7 | AN10: 9.7
A11: ar3dson@gmail.com | B11: Alex | C11: Edson | D11: Alex Edson | E11: 7.6 | F11: 2357064 | G11: Confirmed | H11: Minerva Golf Club | I11: 33816 | J11: M | L11: member | M11: 1 | N11: 1 | Q11: 789 Hammond Dr | R11: Apt 3301 | S11: Atlanta | T11: Yes | Z11: 2348481 | AA11: Ashby Foltz | AB11: 17.7 | AC11: 17.7 | AD11: 18.1 | AE11: 18.4 | AF11: 18.4 | AG11: 17.6 | AH11: 17.6 | AI11: 15.8 | AJ11: 15.8 | AK11: 15.8 | AL11: 15.4 | AM11: 14.9 | AN11: 14.8
A12: afoltz3@gmail.com | B12: Ashby | C12: Foltz | D12: Ashby Foltz | E12: 17.8 | F12: 2348481 | G12: Confirmed | H12: Minerva Golf Club | I12: 32582 | J12: M | L12: member | M12: 15 | N12: 15 | Q12: 500 Emory Circle NE | S12: Atlanta | T12: Yes | Z12: 10275275 | AA12: Nick Johnson | AB12: 27.1 | AC12: 27.1 | AD12: 27.1 | AE12: 27.1 | AF12: 27.1 | AG12: 27.1 | AH12: 27.1 | AI12: 25.6 | AJ12: 25.6 | AK12: 25.6 | AL12: 25.6 | AM12: 25.6 | AN12: 25.6
A13: nick.johnson810@gmail.com | B13: Nick | C13: Johnson | D13: Nick Johnson | E13: 28.6 | F13: 10275275 | G13: Confirmed | H13: Minerva Golf Club | I13: 32365 | J13: M | L13: member | M13: 19 | N13: 19 | Q13: 339 W 16th St | S13: Houston | T13: Yes | Z13: 11102154 | AA13: Jay Kornder II | AB13: 33 | AC13: 33 | AD13: 33 | AE13: 33 | AF13: 33 | AG13: 33 | AH13: 33.8 | AI13: 32.4 | AJ13: 32.4 | AK13: 32.4 | AL13: 32.4 | AM13: 32.4 | AN13: 32.4
A14: gmlane@gmail.com | B14: George | C14: Lane | D14: George Lane | E14: 10.7 | F14: 2699107 | G14: Confirmed | H14: Minerva Golf Club | I14: 32346 | J14: M | L14: member | M14: 2 | N14: 2 | Q14: 476 Wilmer St NE Unit 1510 | S14: Atlanta | T14: Yes | Z14: 2699107 | AA14: George Lane | AB14: 10.2 | AC14: 9.8 | AD14: 8.6 | AE14: 8.6 | AF14: 8.6 | AG14: 8.6 | AH14: 8.6 | AI14: 6.7 | AJ14: 6.7 | AK14: 6.7 | AL14: 6.7 | AM14: 6.7 | AN14: 6.7
A15: mastrangeloms@gmail.com | B15: Marc | C15: Mastrangelo | D15: Marc Mastrangelo | E15: 27.3 | F15: 10477569 | G15: Confirmed | H15: Minerva Golf Club | I15: 32606 | J15: M | L15: member | M15: 21 | N15: 21 | Q15: 227 N Central Ave | S15: Campbell | T15: Yes | Z15: 10477569 | AA15: Marc Mastrangelo | AB15: 28.7 | AC15: 28.8 | AD15: 28.8 | AE15: 28.8 | AF15: 28.8 | AG15: 28.8 | AH15: 28.8 | AI15: 28.8 | AJ15: 28.8 | AK15: 28.3 | AL15: 28 | AM15: 27.3 | AN15: 26.7
A16: dmustard@gmail.com | B16: David | C16: Mustard | D16: David Mustard | E16: 10.6 | F16: 2155192 | G16: Confirmed | H16: Minerva Golf Club | I16: 30785 | J16: M | L16: member | M16: 14 | N16: 14 | Q16: 3058 Gant Quarters Cir | S16: Marietta | T16: Yes | Z16: 10267277 | AA16: Ryan Morrissey | AB16: 7.4 | AC16: 6.6 | AD16: 6.6 | AE16: 4.5 | AF16: 4.5 | AG16: 3.9 | AH16: 3.9 | AI16: 3.9 | AJ16: 3.9 | AK16: 3.9 | AL16: 3.9 | AM16: 3.9 | AN16: 3.9
A17: johnprichards3@gmail.com | B17: John | C17: Richards | D17: John Richards | E17: 24.2 | F17: 10662253 | G17: Confirmed | H17: Minerva Golf Club | J17: M | L17: member | M17: 20 | N17: 20 | Q17: 1875 Woodland Hills Ave NW | S17: Atlanta | T17: Yes | Z17: 2155192 | AA17: David Mustard | AB17: 11.2 | AC17: 11.3 | AD17: 11.3 | AE17: 11.3 | AF17: 11.3 | AG17: 11.3 | AH17: 11.3 | AI17: 11.3 | AJ17: 11.5 | AK17: 11.5 | AL17: 11 | AM17: 10.6 | AN17: 11
A18: saebobbyross@gmail.com | B18: Bobby | C18: Ross | D18: Bobby Ross | E18: 16.2 | F18: 2348449 | G18: Confirmed | H18: Minerva Golf Club | I18: 32318 | J18: M | L18: member | M18: 11 | N18: 11 | Q18: 3500 Brookfield Dr | S18: Greensboro | T18: Yes | Z18: 10662253 | AA18: John Richards | AB18: 25.5 | AC18: 25.5 | AD18: 25.5 | AE18: 25.5 | AF18: 25.5 | AG18: 25.5 | AH18: 25.8 | AI18: 25.8 | AJ18: 25.8 | AK18: 25.8 | AL18: 25.5 | AM18: 24.7 | AN18: 24.7
A19: zackpetaylor@gmail.com | B19: Zachary | C19: Taylor | D19: Zachary Taylor | E19: 10.4 | F19: 3198866 | G19: Confirmed | J19: M | L19: member | M19: 4 | N19: 4 | T19: Yes | Z19: 2348449 | AA19: Bobby Ross | AB19: 15.8 | AC19: 15.8 | AD19: 15.8 | AE19: 15.8 | AF19: 15.8 | AG19: 15.8 | AH19: 15.8 | AI19: 15.4 | AJ19: 15.4 | AK19: 15.4 | AL19: 15.4 | AM19: 15.4 | AN19: 15.4
A20: vhwestphal@gmail.com | B20: Hastings | C20: Westphal | D20: Hastings Westphal | E20: 12.9 | F20: 2530813 | G20: Confirmed | J20: M | L20: member | M20: 8 | N20: 8 | T20: Yes

Sheet Current Event Scores
A1: Name | B1: Over Par | C1: Thru | D1: Display Projection? | E1: Handicap | F1: Course (optional) | G1: Rating | H1: Slope | I1: Gross Score (optional) | J1: # of Holes | K1: Par | L1: Actual Gross | M1: Net Score | N1: Projected Gross | O1: Actual Scratch | P1: Projected Scratch | Q1: Projected Net | R1: Event Type | S1: Photo | T1: Entered by | U1: Created Date/Time | V1: Formatted Created Dttm | W1: Tee Time | X1: Tee Time (to date) | Y1: ID | Z1: Last Updated By | AA1: Last Updated Time | AB1: Formatted Last Updated Dttm | AC1: Entered By Name | AD1: Updated By Name | AE1: Gross (Net) or Tee Time | AF1: Gross (Net) or empty | AG1: Tee Time or Empty | AH1: Total Thru | AI1: Total Over Par | AJ1: Total Over Par (Formatted) | AK1: Gross (Actual Scratch) | AL1: Gross (Projected Scratch) | AM1: Round Progress | AN1: Event Name | AO1: Net Event Points | AP1: Scratch Event Points | AQ1: Hide from score list | AR1: Score Image | AS1: NCRDB | AT1: Score Needed for E | AU1: Me vs. Other Member | AV1: Selected Member | AW1: Thru 0,9,18 (0,1,2,3) | AX1: Total Thru with Override | AY1: Current Location | AZ1: Golfer | BA1: Course | BB1: Thru | BC1: Score
A2: {=if(len(F2:F52)=0,"",if(AU2:AU52="Me",AC2:AC52,AV2:AV52))} | D2: {=IF(LEN(A2:A52) = 0, "", "Y")} | E2: {=IF(LEN(A2:A52) = 0, "", if(J2:J52=18,vlookup(A2:A52,Profile!A$2:E52,3,false),vlookup(A2:A52,Profile!A$2:F52,5,false)))} | G2: {=IF(LEN(F2:F52) = 0, "", vlookup(F2:F52,Courses!A:H,5,false))} | H2: {=IF(LEN(F2:F52) = 0, "", vlookup(F2:F52,Courses!A:H,6,false))} | J2: {=IF(LEN(F2:F52) = 0, "", vlookup(F2:F52,Courses!A:H,7,false))} | K2: {=IF(LEN(F2:F52) = 0, "", vlookup(F2:F52,Courses!A:H,8,false))} | L2: {=if(len(A2:A52)=0,"",if(len(I2:I52)>0,I2:I52,K2:K52+B2:B52))} | M2: {=IF(LEN(A2:A52) = 0, "",ROUND(I2:I52-round(Controls!W2*(((E2:E52*H2:H52)/113)+(G2:G52-K2:K52)),0)-K2:K52,0) )} | N2: {=IF(LEN(A2:A52) = 0, "",round((B2:B52+(round(Controls!W2*((E2:E52*H2:H52/113)+(G2:G52-K2:K52)),0)/J2:J52)*(J2:J52-C2:C52)+K2:K52),0))} | O2: {=IF(LEN(A2:A52) = 0, "",if(len(C2:C52) + len(I2:I52) = 0,"",if(len(I2:I52) > 0, I2:I52-round(((0*H2:H52)/113)+(G2:G52-K2:K52),0)-K2:K52, ROUND(L2:L52-round(((0*H2:H52)/113)+(G2:G52-K2:K52),0)-K2:K52,0))))} | P2: {=IF(LEN(A2:A52) = 0, "",if(len(C2:C52) + len(I2:I52) = 0,"",if(len(I2:I52) > 0, I2:I52-round(((0*H2:H52)/113)+(G2:G52-K2:K52),0)-K2:K52, ROUND(N2:N52-round(((0*H2:H52)/113)+(G2:G52-K2:K52),0)-K2:K52,0))))} | Q2: {=IF(LEN(A2:A52) = 0, "",if(len(C2:C52) + len(I2:I52) = 0,"",if(len(I2:I52) > 0, M2:M52, ROUND(N2:N52-round(Controls!$W$2*((E2:E52*H2:H52/113)+(G2:G52-K2:K52)),0),0)-K2:K52)))} | R2: {=IF(LEN(A2:A52) = 0, "",Types!G2)} | S2: {=IF(LEN(A2:A52) = 0, "", vlookup(A2:A52,Profile!A$2:F52,6,false))} | V2: {=IF(LEN(A2:A52) = 0, "", TEXT(U2:U52,"M/D/YY - H:MM AM/PM"))} | X2: {=if(len(A2:A52)=0,"",text(W2:W52,"DDD M/D - H:MM AM/PM"))} | AB2: {=IF(LEN(AA2:AA52) = 0, "", TEXT(AA2:AA52,"M/D/YY - H:MM AM/PM"))} | AC2: {=IF(LEN(T2:T52) = 0, "", vlookup(T2:T52,Profile!B$2:J52,9,false))} | AD2: {=IF(LEN(Z2:Z52) = 0, "", vlookup(Z2:Z52,Profile!B$2:J52,9,false))} | AE2: {=IF(LEN(A2:A52) = 0, "", if(len(AH2:AH52)= 0,"Tee Time: " & if(len(W2:W52)=0,text(U2:U52,"DDD M/D - H:MM AM/PM"),text(W2:W52,"DDD M/D - H:MM AM/PM")),if(Q2:Q52>0,AJ2:AJ52 &"(+"&Q2:Q52 & ")" & " " & AH2:AH52,if(Q2:Q52=0,AJ2:AJ52 &"(E)" & " " & AH2:AH52,AJ2:AJ52 &"(" & Q2:Q52 & ")" & " " & AH2:AH52))))} | AF2: {=IF(LEN(A2:A52) = 0, "", if(len(AH2:AH52)= 0,"",if(Q2:Q52>0,AJ2:AJ52 &"(+"&Q2:Q52 & ")" & " " & AH2:AH52,if(Q2:Q52=0,AJ2:AJ52 &"(E)" & " " & AH2:AH52,AJ2:AJ52 &"(" & Q2:Q52 & ")" & " " & AH2:AH52))))} | AG2: {=IF(LEN(A2:A52) = 0, "", if(len(AH2:AH52)= 0,if(len(W2:W52)=0,text(U2:U52,"M/D/YY - H:MM AM/PM"),text(W2:W52,"DDD M/D - H:MM AM/PM")),""))} | AH2: {=IF(LEN(A2:A52) = 0, "", if(len(I2:I52)> 0,"Thru F",if(J2:J52=C2:C52,"Thru F",if(len(C2:C52)>0,"Thru " & C2:C52,""))))} | AI2: {=IF(LEN(A2:A52) = 0, "", if(len(B2:B52) + (I2:I52) = 0,"", if(len(I2:I52)> 0,I2:I52-K2:K52,B2:B52)))} | AJ2: {=IF(LEN(A2:A52) = 0, "", if(AI2:AI52 = 0,"E",if(AI2:AI52 < 0,AI2:AI52,if(len(AI2:AI52) > 0 ,"+" & AI2:AI52,if(len(AI2:AI52) = 0 ,"E" ,AI2:AI52)))))} | AK2: {=IF(LEN(A2:A52) = 0, "", if(len(AH2:AH52)= 0,"",if(O2:O52>0,AJ2:AJ52 &"(+"&O2:O52 & ")" & " " & AH2:AH52,if(O2:O52=0,AJ2:AJ52 &"(E)" & " " & AH2:AH52,AJ2:AJ52 &"(" & O2:O52 & ")" & " " & AH2:AH52))))} | AL2: {=IF(LEN(A2:A52) = 0, "", if(len(AH2:AH52)= 0,"",if(P2:P52>0,AJ2:AJ52 &"(+"&P2:P52 & ")" & " " & AH2:AH52,if(P2:P52=0,AJ2:AJ52 &"(E)" & " " & AH2:AH52,AJ2:AJ52 &"(" & P2:P52 & ")" & " " & AH2:AH52))))} | AM2: {=if(len(A2:A52)=0,"",if(len(I2:I52)>0,18,if(C2:C52="",0,(if(J2:J52=9,C2:C52*2,C2:C52)))))} | AN2: {=IF(LEN(A2:A52) = 0, "",Types!H2)} | AO2: {=IF(LEN(A2:A52) = 0, "", vlookup(Y2:Y52,'Scores + Points'!A$2:Z52,20,false))} | AP2: {=IF(LEN(A2:A52) = 0, "", vlookup(Y2:Y52,'Scores + Points'!A$2:Z52,24,false))} | AR2: {=IFERROR(VLOOKUP(Q2:Q52,'Score Images'!A2:C52,3,false),"")} | AS2: {=if(len(A2:A52)=0,"","http://ncrdb.usga.org/")} | AT2: {=IF(LEN(A2:A52) = 0, "",round(Controls!W2*(((E2:E52*H2:H52)/113)+(G2:G52-K2:K52)),0)+K2:K52)} | AW2: {=IF(LEN(A2:A52) = 0, "",if(AX2:AX52="",0,if(AX2:AX52<1,0,if(AX2:AX52<9,0,if(AX2:AX52<18,2,if(AX2:AX52=18,3))))))} | AX2: {=if(len(A2:A52)=0,"",if(len(I2:I52)>0,J2:J52,if(C2:C52="","",C2:C52)))} | AZ2: {=IF(LEN(A2:A52) = 0, "", A2:A52)} | BA2: {=IF(LEN(A2:A52) = 0, "", F2:F52)} | BB2: {=IF(LEN(A2:A52) = 0, "", C2:C52)} | BC2: {=IF(LEN(A2:A52) = 0, "", B2:B52)}
A3: Robby Dewling | D3: Y | E3: 6.1 | F3: Echelon Golf Club - Blue (18 Holes) | G3: 72.3 | H3: 138 | I3: 88 | J3: 18 | K3: 72 | L3: 88 | M3: 9 | N3: 79 | O3: 16 | P3: 16 | Q3: 9 | R3: M | S3: https://storage.googleapis.com/glide-prod.appspot.com/uploads-v2/GNXfNUSV91nct3RVn9zd/pub/wD9y0NT35v2ch7ZEGxQP.jpeg | T3: rdewling@gmail.com | U3: 45878.892 | V3: 8/9/25 - 9:24 PM | W3: 45878.892 | X3: Sat 8/9 - 9:24 PM | Y3: 22afcbf8-018a-40f0-a9b3-1751d57cf998 | AC3: Robby Dewling | AE3: +16(+9) Thru F | AF3: +16(+9) Thru F | AH3: Thru F | AI3: 16 | AJ3: +16 | AK3: +16(+16) Thru F | AL3: +16(+16) Thru F | AM3: 18 | AN3: 12 | AO3: 4.6 | AP3: 7.6 | AR3: https://lh3.googleusercontent.com/Y1BGH5wfNUq_6FALjd6GJM9u9uoPOYcyGex1XAxsRdOzIPEnKzIoymBsuWd3FnkIh1sADPvhnLckSPvau475e1Frgdztu2vmyrBE4g0InPaiSlscKMyL02ub1dmA-77T2qpA9WSb20TUT5avXawNU2UnKg740z--El6KHjPP6dKkKWpzzl8aUvQYtHm7RQDjqtpLfljwkHHqfewL5Oo2pcKfbxq41gA-3e-4qvSABiUn5zXFnWZOmGyuqNPXZ36dzqs74uZvxaLVCXDLflg4lnu6iKwW3a8vZkaNBhp5wJQvNKtv2kPvSksFNazb94cwWZSQj_WqsaFE9otVXlC18dycsPOYW4O2jvB5h5QYhUVryYQcdQ1VOpdb5e5shlb4oTeMgtQ6nWd_nARV_v0xk3wUqQI3pvtN_fxeWuS5sHdlwpDAiOpq9tIAeLdIm2gn_OauOAcrx0qc0eBPETSvtbpLBhMjkFxATYQnRenQaIW-yGsvyPz2qx__oS3VHgHgG1IprArR_3qS8QsSrlTQwaXJDsoWSVIsP5QRY-DgzBvTpcYFa9nZMGDuIp-R_Qn0EJvxyyofz79nLB0LrHPJQOwOvg0NBThMsbMevzMmIOAAjofOchigr46t_y63ajVNT1PqB7KBAfPgoDtGUlqyzsXQcUor1RJlTV9FnHIHEdPJ79qYPRZvPO2C=w116-h103-no | AS3: http://ncrdb.usga.org/ | AT3: 79 | AU3: Me | AW3: 3 | AX3: 18 | AZ3: Robby Dewling | BA3: Echelon Golf Club - Blue (18 Holes)
A5: Cory Arnwine | B5: 20 | C5: 18 | D5: Y | E5: 14.5 | F5: Elie - White (18 Holes) | G5: 70.5 | H5: 124 | J5: 18 | K5: 70 | L5: 90 | M5: -86 | N5: 90 | O5: 19 | P5: 19 | Q5: 4 | R5: M | S5: https://storage.googleapis.com/glide-prod.appspot.com/uploads-v2/GNXfNUSV91nct3RVn9zd/pub/ZVOcGslXfVNwGSOfc3Rm.jpeg | T5: carnwine@gmail.com | U5: 45887.349 | V5: 8/18/25 - 8:22 AM | W5: 45887.625 | X5: Mon 8/18 - 3:00 PM | Y5: 6af22a98-2476-46e9-a505-7687560e5756 | AC5: Cory Arnwine | AE5: +20(+4) Thru F | AF5: +20(+4) Thru F | AH5: Thru F | AI5: 20 | AJ5: +20 | AK5: +20(+19) Thru F | AL5: +20(+19) Thru F | AM5: 18 | AN5: 12 | AO5: 10.6 | AP5: 4.6 | AR5: https://lh3.googleusercontent.com/X9NboRI9tXpfX4phhLZVYexHVnQAJBEoc0hBQVGKHHqWBul-E9E_TgJvwHNjt7LQjZOFV-9kYbZ9XphA5rbyC7zyZNjaUVjEiOENCW7vMoC5MjbgxAilXTyc9CYSOAgrCUmmmMYTIggYHJQkbY4dFSEXBJ8CIKUtRqX_CzpCKLlVG4kp_4eVVYlZaKU_7YQXUIjVGwzH0ZxJF315f5lY0iVnSlj606BU3XEz-vbOY0jk2h0oHdwfrDebb19DXndyl5kwTSXapNeSVWdutJIvhOdHtWBCieEJqW7gB_NWYdSTsAAB-IXNdV27cGYjCywVvoDNtxe4Phb0twHtHJqAPGIl2u7xMd72IQ5QQD9UQPmwgI4u2vk7jvwA9agTu-xLOfYMXkvrDlwWdkSQl_Yw3IcN90qVXfi0k7_AbklUTfOi3-S9IWFUXtgy1Cgt_E6yQB7-PBZyDo19DoW5vHtfmqBb8T5E8P2QzmB5dRpfgMAe8TO9PWZngokrrJVizc8BdIuEHJ2wTTcIHDuurywX6XICUy1ef5WWp6pYmVEVslCCFL4xczkTi4vwT_tiaKGQVEt0rJ-4U26ZsICBHFRTocCAmN_qsmdCmgzI_u7Gsyr4glyhOh6p_uDTGA-1kx12K_Qc_mq-ASZkVZLc8KM0LlHGSumasNaXYDqnV5Bvq0FGCfp2vgwvOd4=w116-h103-no | AS5: http://ncrdb.usga.org/ | AT5: 86 | AU5: Me | AW5: 3 | AX5: 18 | AZ5: Cory Arnwine | BA5: Elie - White (18 Holes) | BB5: 18 | BC5: 20
A6: Cory Arnwine | B6: 8 | C6: 18 | D6: Y | E6: 14.5 | F6: Lundin Golf Club - Yellow (18 Holes) | G6: 70.2 | H6: 130 | J6: 18 | K6: 71 | L6: 79 | M6: -86 | N6: 79 | O6: 9 | P6: 9 | Q6: -7 | R6: M | S6: https://storage.googleapis.com/glide-prod.appspot.com/uploads-v2/GNXfNUSV91nct3RVn9zd/pub/ZVOcGslXfVNwGSOfc3Rm.jpeg | T6: carnwine@gmail.com | U6: 45887.395 | V6: 8/18/25 - 9:28 AM | W6: 45887.401 | X6: Mon 8/18 - 9:38 AM | Y6: 0df8560c-5c66-42f9-b92e-478d57ec0257 | AC6: Cory Arnwine | AE6: +8(-7) Thru F | AF6: +8(-7) Thru F | AH6: Thru F | AI6: 8 | AJ6: +8 | AK6: +8(+9) Thru F | AL6: +8(+9) Thru F | AM6: 18 | AN6: 12 | AO6: 10.6 | AP6: 4.6 | AR6: https://lh3.googleusercontent.com/9IxIsPmI2L6ehbUx31jaId8YTx4Uf04R_OGSMAVzF4INV-PxuqGsf-Sj-EzNFF_EIJm_SsuGYrBSEdd2hOvIRfG8ORY2isaExX6YzEme5hI5jp-puAG6cRzaqXXA4Wbar8i1Atm4xhIldLSfaHb5jRJXdx6MCy1YBMZZXkx4DSoxgGec4kMEB7BJmtShIwYq9AOOcGWiqLoNfobwu42U8d4rgiEGgEnM7NI9Z_wTHp9Hw3Zd9pR3AgZfwPgZWueD5Be_E9m-qqNK2PAmqueSlD1JDlK5QCFWgjsNMHSYuA2z3Ul_-qT0sdAosGuxo-KJBod9J8LaTrYiEqGfQ55CtdiZw9wUGqNpzzNzmCOSNSe74sMHDVreudqowdE65JmvsbwNC5POWlFe8W50qHARP4wO8HB3ZzQRe1IbfkLOtX1HCVPjcFD0lRjH7Ix4X8O-g9_2UaFbCubLH9SByBFEwLd-UY6c4bynOJGFpyp_838VOhTA5Ubkkb15yrI-uRm5zgNloWU3iOGoKmjkYKOzM6b3gJtmLuBa3MzyoPRWjuLLL-_2vSv4hshSwapR06rR-NCywdgm_1JpICRhOCbRKJ1twztIlpyKYkELf47oi1xSz-SZ7R-j71YBg0nHVM9pcDB_byRKNPzL4I8YPnHGQvz6O7yrwGE0mRgSaHEHiM3EQN1aRDIxzQo=w116-h103-no | AS6: http://ncrdb.usga.org/ | AT6: 86 | AU6: Me | AW6: 3 | AX6: 18 | AZ6: Cory Arnwine | BA6: Lundin Golf Club - Yellow (18 Holes) | BB6: 18 | BC6: 8
A7: Ashby Foltz | D7: Y | E7: 17.8 | F7: Elie - White (18 Holes) | G7: 70.5 | H7: 124 | I7: 91 | J7: 18 | K7: 70 | L7: 91 | M7: 2 | N7: 89 | O7: 20 | P7: 20 | Q7: 2 | R7: M | S7: https://minervatour.files.wordpress.com/2019/10/img_5277.jpg | T7: afoltz3@gmail.com | U7: 45887.899 | V7: 8/18/25 - 9:34 PM | Y7: 01553992-5646-47e4-8564-28c3da1ea871 | AC7: Ashby Foltz | AE7: +21(+2) Thru F | AF7: +21(+2) Thru F | AH7: Thru F | AI7: 21 | AJ7: +21 | AK7: +21(+20) Thru F | AL7: +21(+20) Thru F | AM7: 18 | AN7: 12 | AO7: 5.6 | AP7: 3.6 | AR7: https://lh3.googleusercontent.com/wXx5aO2MitxNB5djH3t6tQ5qanOQLB2REHjUtBXGFtgKXmXD03ezp4rgby-1tFUVAbse9f5ScSZc71nI0g2qCi9Cay7PKhEa4e-mLVWXYYeEkid4MqrRFAXwCst3P7k3GyJlEHagAc8rXRTdDMFGIXw0hhNh4Je8M2JpPcS7qyIgNoZ3IlJnPAB2jLcF3zP9RlXtPhRQ-Ly9FS6J_7L0Bh5sivSzUWCz9ILpGMRfP6sbKpzOHK2aZn1-uipLAWuulVv9j9wpHxAcvmYUpeI6Dl9n59qOzkMea9ED25YlCpn1S-kj_tFs_7USxkTlld-i6qmYqpCj_o5pCdNYE7Rcn5bRf9AnJkbbQR9s7M1ZsoMqi2w4yzhJ8WumUWLRy_A_AQdM7EYNQZJCep-bPyg-ejqMNxmoT1Zrbx-1C_cvrCe5T4nbJF1Z1reiCyC_CgR37Uvt8kPfBtRdXWZxsb-mXFwT7mdtj9H8ohmAuM2oCm8Jwat1fpkhpFrmRcrYodWAJZx6xAmGHTsekpFV40Fvr1gFOwdn90bDuHofViSoepYiaq1WLK8o6sEEn0ATIOVCxZjl1UdhC6U22GMeChfJfJ8BPL_EsESYmE3wHMNdKTHzG1g0BYS9Xu1jfdG8PxNq9U1Vm3GU6R6hHUaELyw_YObN0SSPkgpH8esf4k1583EbAA2A9W4ONStn=w116-h102-no | AS7: http://ncrdb.usga.org/ | AT7: 89 | AU7: Me | AW7: 3 | AX7: 18 | AZ7: Ashby Foltz | BA7: Elie - White (18 Holes)
A8: Bobby Ross | D8: Y | E8: 16.2 | F8: Elie - White (18 Holes) | G8: 70.5 | H8: 124 | I8: 89 | J8: 18 | K8: 70 | L8: 89 | M8: 2 | N8: 87 | O8: 18 | P8: 18 | Q8: 2 | R8: M | S8: https://firebasestorage.googleapis.com/v0/b/glide-prod.appspot.com/o/img-uploads%2FGNXfNUSV91nct3RVn9zd%2F7ede3f.jpeg?alt=media | T8: saebobbyross@gmail.com | U8: 45887.899 | V8: 8/18/25 - 9:35 PM | W8: 45887.625 | X8: Mon 8/18 - 3:00 PM | Y8: 49e0a881-e98a-4c93-a953-6c76d6ea2915 | AC8: Bobby Ross | AE8: +19(+2) Thru F | AF8: +19(+2) Thru F | AH8: Thru F | AI8: 19 | AJ8: +19 | AK8: +19(+18) Thru F | AL8: +19(+18) Thru F | AM8: 18 | AN8: 12 | AO8: 3.6 | AP8: 0.6 | AR8: https://lh3.googleusercontent.com/wXx5aO2MitxNB5djH3t6tQ5qanOQLB2REHjUtBXGFtgKXmXD03ezp4rgby-1tFUVAbse9f5ScSZc71nI0g2qCi9Cay7PKhEa4e-mLVWXYYeEkid4MqrRFAXwCst3P7k3GyJlEHagAc8rXRTdDMFGIXw0hhNh4Je8M2JpPcS7qyIgNoZ3IlJnPAB2jLcF3zP9RlXtPhRQ-Ly9FS6J_7L0Bh5sivSzUWCz9ILpGMRfP6sbKpzOHK2aZn1-uipLAWuulVv9j9wpHxAcvmYUpeI6Dl9n59qOzkMea9ED25YlCpn1S-kj_tFs_7USxkTlld-i6qmYqpCj_o5pCdNYE7Rcn5bRf9AnJkbbQR9s7M1ZsoMqi2w4yzhJ8WumUWLRy_A_AQdM7EYNQZJCep-bPyg-ejqMNxmoT1Zrbx-1C_cvrCe5T4nbJF1Z1reiCyC_CgR37Uvt8kPfBtRdXWZxsb-mXFwT7mdtj9H8ohmAuM2oCm8Jwat1fpkhpFrmRcrYodWAJZx6xAmGHTsekpFV40Fvr1gFOwdn90bDuHofViSoepYiaq1WLK8o6sEEn0ATIOVCxZjl1UdhC6U22GMeChfJfJ8BPL_EsESYmE3wHMNdKTHzG1g0BYS9Xu1jfdG8PxNq9U1Vm3GU6R6hHUaELyw_YObN0SSPkgpH8esf4k1583EbAA2A9W4ONStn=w116-h102-no | AS8: http://ncrdb.usga.org/ | AT8: 87 | AU8: Me | AW8: 3 | AX8: 18 | AZ8: Bobby Ross | BA8: Elie - White (18 Holes)
A9: Alex Edson | D9: Y | E9: 7.6 | F9: Elie - White (18 Holes) | G9: 70.5 | H9: 124 | I9: 95 | J9: 18 | K9: 70 | L9: 95 | M9: 17 | N9: 78 | O9: 24 | P9: 24 | Q9: 17 | R9: M | S9: https://storage.googleapis.com/glide-prod.appspot.com/uploads-v2/GNXfNUSV91nct3RVn9zd/pub/MXbvc7EbvlbCRBjsPjcA.jpg | T9: carnwine@gmail.com | U9: 45887.902 | V9: 8/18/25 - 9:38 PM | X9: Sat 12/30 - 12:00 AM | Y9: 26d87c10-1ccf-45dc-a98f-404aa04d77a8 | AC9: Cory Arnwine | AE9: +25(+17) Thru F | AF9: +25(+17) Thru F | AH9: Thru F | AI9: 25 | AJ9: +25 | AK9: +25(+24) Thru F | AL9: +25(+24) Thru F | AM9: 18 | AN9: 12 | AO9: 1 | AP9: 1.6 | AR9: https://lh3.googleusercontent.com/SovAg0t0zByaah0O2LBG7X8ZgHdm1Rnr8iq0Yot6CC74iLKZgm-7UR7jnvzqr14OTS-0L-G1PSoEfP2gBvHgkQ9ojAvtKOuYwHOj5tXNst6hqSdtInLV74pR0EzlrpV2oCjVAHgHVPl9EynsvYKoa7lzAhW-NbkqkQkg_SfXZ8zahfrtg9BkF0y3A3gA9LTuu2enEgz61mBVM-4I-cNzUXiwLjNWDYXE4ljcTR2T-x0caUr4wuXpMeVP5RBApdCo2tq2cLeTQtHV-YyKMJxKz2X4sVv-hvNRcN7ejYqV2qepaWE6erOPQ3TKChzBIwAB1gcTqt8coJ_hQMEK0gFIe8OtY-j_UCEozQwTGuJh3aoG8sa01-fk-fSHr1hOQvbrQMkbJTMiZNrZBzAjxDjlXYwry7SS03g5tom3b-WL_e_B6cdkDd6oT-xjHN2-3BlrBFkGblVGORc95gSP9_0rvmtnocHbl3imyQijOlYD742zYjYSDmt8hBItXesObR6y19j6ycZQdzthafRXcAeNQpvlZqkhJ7Pb-jn2B7IAyKouK2z9pvy6WJY2I61xMTPwPx69zXLmxD5hKL76QzasmA4bLmPkFfMRskS0behOb9_O0OWY64oLOlraiuIrUEbo07sstA7wD75xuQFW0Z9dCEBoxx-WpvKIc2DVIZpFg1g1cPUqrTBfUes=w116-h103-no | AS9: http://ncrdb.usga.org/ | AT9: 78 | AU9: Other Member | AV9: Alex Edson | AW9: 3 | AX9: 18 | AZ9: Alex Edson | BA9: Elie - White (18 Holes)
A10: Cory Arnwine | B10: 13 | C10: 18 | D10: Y | E10: 14.5 | F10: St. Andrews - Eden - White (18 Holes) | G10: 70.6 | H10: 126 | J10: 18 | K10: 70 | L10: 83 | M10: -86 | N10: 83 | O10: 12 | P10: 12 | Q10: -3 | R10: M | S10: https://storage.googleapis.com/glide-prod.appspot.com/uploads-v2/GNXfNUSV91nct3RVn9zd/pub/ZVOcGslXfVNwGSOfc3Rm.jpeg | T10: carnwine@gmail.com | U10: 45888.02 | V10: 8/19/25 - 12:29 AM | W10: 45888.394 | X10: Tue 8/19 - 9:28 AM | Y10: cc273c27-8f66-4a16-9b4a-43753a76885f | AC10: Cory Arnwine | AE10: +13(-3) Thru F | AF10: +13(-3) Thru F | AH10: Thru F | AI10: 13 | AJ10: +13 | AK10: +13(+12) Thru F | AL10: +13(+12) Thru F | AM10: 18 | AN10: 12 | AO10: 10.6 | AP10: 4.6 | AR10: https://lh3.googleusercontent.com/tX5Isztzx1OoFrPJNQkRfEEnBALLLhljVk1z80zv_uyBL4aMbZVnqpDtitxxFPM7ba47NULJ4nGCG0AhgY9x6tILqDQKPVzT9XDkSA9CjnZlAQFccDnkUBUVlPVIJJyRAWW6vZ5315R_bTfRcxvv9814_fdU_FoSYaHqA87EMkoFWL27VhQTPrTIdI6SQZwLsOt0sc97iUhA2lL0NWlKYcXxM0xYQc7MJXXNK_LR2KoAMG05NjpkcqB4nDfm0NxdQnroQcn0IJDf2cyBirOAi8gBCxJwHKcpBxUTBHO158-65jMwmKZa7Fs8UKOvS_vUG8PUYEVSOIwKuOqUbOc7eXZkYqnub1LQgwMTyq3-ISnSSNcT70q7EcyesVlLM4YV6FZpEWSThmXLfvakkpeLPnLnrnoS3qBTH_84BaJG9OdJxQ28nzkPYXQPgjRBkClUzctGVqfDB2pQvQplUu7kTktEdiHSDj1N9OJ9AXggg9NT-pMMGWmI78GDuxT2vtOXMzr35y-jupJPeR4F6o2_ryCqIZmCJNBJgOCw3cpnv3BYyW0vQFEEUZQiL4N2UtYGs8KX-P_wV_0UlokPGH4JSFvjrpAhEREzun9Yb5GmUWPmuC1mcUHwz6BPxWxpn9ky0igAIwttMcsrUvMBrSoTfGbqXYfasTOCnzmKcsY96UxDDpWdqCVE5Cg=w116-h103-no | AS10: http://ncrdb.usga.org/ | AT10: 86 | AU10: Me | AW10: 3 | AX10: 18 | AZ10: Cory Arnwine | BA10: St. Andrews - Eden - White (18 Holes) | BB10: 18 | BC10: 13
A11: Cory Arnwine | B11: 21 | C11: 18 | D11: Y | E11: 14.5 | F11: St. Andrew’s - New Course - Yellow (18 Holes) | G11: 70.6 | H11: 125 | J11: 18 | K11: 71 | L11: 92 | M11: -86 | N11: 92 | O11: 21 | P11: 21 | Q11: 6 | R11: M | S11: https://storage.googleapis.com/glide-prod.appspot.com/uploads-v2/GNXfNUSV91nct3RVn9zd/pub/ZVOcGslXfVNwGSOfc3Rm.jpeg | T11: carnwine@gmail.com | U11: 45888.02 | V11: 8/19/25 - 12:29 AM | W11: 45888.628 | X11: Tue 8/19 - 3:04 PM | Y11: e02b755f-f63a-44bf-9f9e-eafd8e9dcdc1 | AC11: Cory Arnwine | AE11: +21(+6) Thru F | AF11: +21(+6) Thru F | AH11: Thru F | AI11: 21 | AJ11: +21 | AK11: +21(+21) Thru F | AL11: +21(+21) Thru F | AM11: 18 | AN11: 12 | AO11: 10.6 | AP11: 4.6 | AR11: https://lh3.googleusercontent.com/Gi7veismj6d99JVt7CQrjL0XTY-r5QRbgyXKckj4F2gupO4EAQeQawfhwK3671nOmSkDxfUGY3sagxYRSrxS4ZD1FNF6zc8P2axGqE7EBKRiAfn7aVVq7tqUieBE4jMdMdMDCbrpiP1JmyzVYdpNiUiG5aSIEYO4M1J_0ymq_YKvWWeGdfBGfk5Kf5k7X-IlDG2FhNMzPw7K0oi1vP5CMr5d1scyhhMEkwV0o_L3-dgG-4dpvwy2omZYIWjRKSSqcxRCcNe04H8dkTLZ7W47ZIL-3XPNI6RXID5cai4FbWkrhq94i7kkk6_B8uYAcVd61_8zfBH0DpBeryEoDnzjuzDj3BeZTavzyb8JBiUdalZKT6cQdoj-JN0Dycm01uT5VVaS6nz81JPy49BEhXJSREV53uq6ZGhECMsDGERamAsUSiMMDHi4Fsfe36LajOyFXsldFOBgN4Q7X5IC29SGRqL2FgEe2fu7XjEjy_YPkJd1AVc816_jKa4HjfA63dq9wBFgJAZFYZYY7OPfhhj5J7hdSrW6H4fAqPNcfC_eYV_cgQjzqZ4IgA8mKYQKyKNpYynZ3vFjKqKlfpaRVe8LqRkG6hoEJ6n94TVVueRRRxw0qTV9c04zmjlgzNO0AM4JO5Dk_b2t2C-EETotBzLQcGqvjQX8FL_lLYhdPlhO6LNdB58HNKEOcXJ_=w116-h103-no | AS11: http://ncrdb.usga.org/ | AT11: 86 | AU11: Me | AW11: 3 | AX11: 18 | AZ11: Cory Arnwine | BA11: St. Andrew’s - New Course - Yellow (18 Holes) | BB11: 18 | BC11: 21
A12: Robby Dewling | D12: Y | E12: 6.1 | F12: St. Andrews - Eden - White (18 Holes) | G12: 70.6 | H12: 126 | I12: 78 | J12: 18 | K12: 70 | L12: 78 | M12: 1 | N12: 77 | O12: 7 | P12: 7 | Q12: 1 | R12: M | S12: https://storage.googleapis.com/glide-prod.appspot.com/uploads-v2/GNXfNUSV91nct3RVn9zd/pub/wD9y0NT35v2ch7ZEGxQP.jpeg | T12: rdewling@gmail.com | U12: 45888.582 | V12: 8/19/25 - 1:58 PM | X12: Sat 12/30 - 12:00 AM | Y12: 16c1e790-e1c1-43e2-abef-c0e111861b3a | AC12: Robby Dewling | AE12: +8(+1) Thru F | AF12: +8(+1) Thru F | AH12: Thru F | AI12: 8 | AJ12: +8 | AK12: +8(+7) Thru F | AL12: +8(+7) Thru F | AM12: 18 | AN12: 12 | AO12: 4.6 | AP12: 7.6 | AR12: https://lh3.googleusercontent.com/tXy0O0LwConoBkdb4wz_YoG_IEPZfDqZaoIDpGZa5CKtCmLmp2m71LbcF8YmiREiuCeOTIHDVTMw9ukeELSKzkHpe6Tnzv8GGoqqLRz_OzkYzSzlGlbVTnatXkvoOqtb9ewJpjyJ9vZFXND4tWRo9Fp1-teBc0O26J_EUhCkbkwjrUgwkZJ8kTNwRkXyojoOJUyExq-zLSMp9XfdiMPYcVcX-BGMUeuytjeJRH8JbyGg1Zuq4sdTcjSd0vGF4le4Ahkf03P2jn4FsfIzVQ3dPjbzePO8kfJVmSLrgi_UnYvLWfNeeonYS1ZXjKs8DombNrdZNj6UXt73utGXVAIK8pH8f15jMtX1RZdNqZ014Awmd0P32v8g2WZ7X_PCAe3eDKqPHSh9UCFgzcuTP97PcMWt5_HQv7VUqqQvCUfCRQWlcgbUdiq5rI5hLD7VnkA8Ul69Hez2lFM2B9FY3rdyZYjrZ-Vq52OPhUe8XNHaYRUWshyjplJjT2kcFs74Bs7ihIoJ-UwJVQdCOqwEEKeYRtQygGAf_IyNCLInI2OpKTw-lY-UOSZTz10f9R9u0RvtWv5LolPzMztNeHcPdq8TzanctW1yQRntXIKXJycEGNEJxOPMoy2ggRWRG6T1ce0BaL7Lk12smXw8Txql7ih_6AmS95k1S7n6XutAkcoY88h1VQ-0WCFP6mM=w116-h103-no | AS12: http://ncrdb.usga.org/ | AT12: 77 | AU12: Me | AW12: 3 | AX12: 18 | AZ12: Robby Dewling | BA12: St. Andrews - Eden - White (18 Holes)
A13: Bobby Ross | D13: Y | E13: 16.2 | F13: St. Andrews - Eden - White (18 Holes) | G13: 70.6 | H13: 126 | I13: 87 | J13: 18 | K13: 70 | L13: 87 | M13: -1 | N13: 88 | O13: 16 | P13: 16 | Q13: -1 | R13: M | S13: https://firebasestorage.googleapis.com/v0/b/glide-prod.appspot.com/o/img-uploads%2FGNXfNUSV91nct3RVn9zd%2F7ede3f.jpeg?alt=media | T13: saebobbyross@gmail.com | U13: 45888.584 | V13: 8/19/25 - 2:00 PM | W13: 45888.403 | X13: Tue 8/19 - 9:40 AM | Y13: 5d61b43f-54c5-4400-abc3-440f023087df | AC13: Bobby Ross | AE13: +17(-1) Thru F | AF13: +17(-1) Thru F | AH13: Thru F | AI13: 17 | AJ13: +17 | AK13: +17(+16) Thru F | AL13: +17(+16) Thru F | AM13: 18 | AN13: 12 | AO13: 3.6 | AP13: 0.6 | AR13: https://lh3.googleusercontent.com/y79LG6IOyNlVI4nffsIu4kI94A0lbmxdi17sZmagyGBM9juhotJIZKgEmCBQ5C6BbuOQynHSrWnhIXR2m9uqHLciIKN2MrW9qbGJyoudCFhpHWtdBTvr-4MZ91EmiAxZo-GLDbymXRZwcNv_4Xx93GIstPTH4x6D4b-eBTuBlH_cMPeKJib5TV0JXyI9l3bReZxhIr7Hr8R4sspZ3z0N5ggeS1646Nh1YTgVyOt76WNYZ7X4P3VNRcYlqSV1yAb6UI4gglnSJ7eJiB3_oQzoCkS95Yv1iwlJcPZokLGVsmMNRugyTGVq5tE5VfB_Dk2UuJPCz8zRm4519cvKV2rULEzDrMc8ExWBi486KOB6ILkTZ17wfSom6dp2awhc1RFxXEWo7hvoYir_JjZyBOgTaqT2QCnNpynOfK8VjCfw8z8rqE-Pdn6z-9wnXKbvolaV4iFENkO_RSjcmm2QgI8BmSzsCioYESsgVYbVlQ9L9oQ-U6K99A1Xbj3F5SGs4Hb2fzqT37cDyzLr7cDeciH-d7Y_yY2MkILh73v3IjJikE66jgVVxBDqrK_Vqqnc-NYzz0jCpKGxIoE3h2-VWCUSmVohoFhCLJacUX-CGyCzDechjKtn9h1jcpE_gXm9lolhadIiGRv41PRR3IYH2vhh4A7QQ_x9E29hO6RPPlRy8ygFeDLiYAeHqUU=w116-h103-no | AS13: http://ncrdb.usga.org/ | AT13: 88 | AU13: Me | AW13: 3 | AX13: 18 | AZ13: Bobby Ross | BA13: St. Andrews - Eden - White (18 Holes)
A14: George Lane | D14: Y | E14: 10.7 | F14: St. Andrews - Eden - White (18 Holes) | G14: 70.6 | H14: 126 | I14: 77 | J14: 18 | K14: 70 | L14: 77 | M14: -5 | N14: 82 | O14: 6 | P14: 6 | Q14: -5 | R14: M | S14: https://firebasestorage.googleapis.com/v0/b/glide-prod.appspot.com/o/img-uploads%2FGNXfNUSV91nct3RVn9zd%2Fb607eb.jpeg?alt=media | T14: gmlane@gmail.com | U14: 45888.585 | V14: 8/19/25 - 2:02 PM | X14: Sat 12/30 - 12:00 AM | Y14: dd993d24-4f91-41d7-bb02-8e8159895c7d | AC14: George Lane | AE14: +7(-5) Thru F | AF14: +7(-5) Thru F | AH14: Thru F | AI14: 7 | AJ14: +7 | AK14: +7(+6) Thru F | AL14: +7(+6) Thru F | AM14: 18 | AN14: 12 | AO14: 7.6 | AP14: 5.6 | AR14: https://lh3.googleusercontent.com/Ic-NM2pPcYVokMRc6R2DIFUy4lMvGrTrLFW-PcP7MTLTloyJdovjG0Gjx4BKZ5XYHYyaDnhBcYPPuUQplWfA9KwCqmN3f0ASBPjRXJY8HoxgFYRfAnLbgiFEE0tw2F-Ej7Doo0Y5eTwwLd5r0c7-aDS_yh3KluTJbiSNVxbuzybPiBfRCVcslk90Ml9kEczo1cSijcK31obbogieSBhiY0eUSidlHSMAYtxG5B_eJVoM62HO8Xxf9v5Dgco8WbfmipZWMBDnDMzfKJU3DbimKx1uYdMwW-V8--xdlR-HfwUhIil-TWixeDyyvmIusmNRtO7lo2JZsWqp3tqWWRdfaNjMDsOi81e_Q5gB-8D6OdZgGCIh6vR39Pc_ImN30dP9YIeugXhnwlr2A6KN3ZAEypFo7VbHt2ZW4lZG7ngtCefbty6N7fepEEfsdUUeye2Q5TYyGz8-wc_BrcHYGxfe12cX61Z4KHRnQlzBz_tH07oV8Q5dQr0A3CEc5UZ2iji2RdOVmQEfg1_N8MealuFDvVrvH2PaQw_sb_YUAhY0RlHoRk1rmc7MamBtVmksqW9XOhdDBPdamrU8eYRMZ7kT7TKGMm_BMQ3rweAfIVstggBFKTw59wu9-vLD-s5SwzEtgonq9qB4y-tk7ZEYyiX0LFBpjFC7huSv_kiTrkbPYWAC8DyM_AvMLNQ=w116-h103-no | AS14: http://ncrdb.usga.org/ | AT14: 82 | AU14: Me | AW14: 3 | AX14: 18 | AZ14: George Lane | BA14: St. Andrews - Eden - White (18 Holes)
I15: 88 | T15: afoltz3@gmail.com | U15: 45888.592 | Y15: c5c3b6c1-dd03-4527-91df-5fb5ef485b23 | AC15: Ashby Foltz | AU15: Me
